<mujoco>
  <option timestep="0.001"/>

  <visual>
    <headlight diffuse="0.6 0.6 0.6" ambient="0.3 0.3 0.3" specular="0 0 0" />
    <rgba haze="0.15 0.25 0.35 1" />
    <global azimuth="160" elevation="-20" />
  </visual>

  <asset>
    <texture type="skybox" builtin="gradient" rgb1="0.3 0.5 0.7" rgb2="0 0 0" width="512" height="3072" />
    <texture type="2d" name="groundplane" builtin="checker" mark="edge" rgb1="0.2 0.3 0.4" rgb2="0.1 0.2 0.3" markrgb="0.8 0.8 0.8" width="300" height="300" />
    <material name="groundplane" texture="groundplane" texuniform="true" texrepeat="5 5" reflectance="0.2" />
  </asset>

  <default>
    <joint type="hinge" axis="0 1 0" limited="false" frictionloss="0.001" armature="0.005" />
    <geom type="cylinder" size="0.02" rgba="0.5 0.5 0.5 1" />
  </default>

  <worldbody>
    <light pos="0 0 3.5" dir="0 0 -1" directional="true" />
    <geom name="floor" size="0 0 0.05" pos="0 0 0" type="plane" material="groundplane" />
    <camera name="fixed" pos="0 -1 0.5" xyaxes="1 0 0 0 0 1" />

    <body name="link1" pos="0 0 0.8">
      <joint name="joint1" type="hinge" axis="0 1 0" limited="false" />
      <geom name="link1_visual" type="capsule" fromto="0 0 0 0.3 0 0" rgba="1 0.3 0.3 1" size="0.03"/>
      
      <body name="link2" pos="0.3 0 0">
        <joint name="joint2" type="hinge" axis="0 1 0" limited="false" />
        <geom name="link2_visual" type="capsule" fromto="0 0 0 0.3 0 0" rgba="0 0 0.5 1" size="0.025"/>
      </body>
    </body>
  </worldbody>

  <actuator>
    <motor name="motor1" joint="joint1" gear="30"/>
    <motor name="motor2" joint="joint2" gear="20"/>
  </actuator>

  <sensor>
    <framepos name="endpoint_pos" objtype="body" objname="link2"/>
  </sensor>
</mujoco>